#VRML_SIM R2023b utf8

EXTERNPROTO "https://raw.githubusercontent.com/cyberbotics/webots/R2023b/projects/objects/backgrounds/protos/TexturedBackground.proto"
EXTERNPROTO "https://raw.githubusercontent.com/cyberbotics/webots/R2023b/projects/objects/backgrounds/protos/TexturedBackgroundLight.proto"
EXTERNPROTO "https://raw.githubusercontent.com/cyberbotics/webots/R2023b/projects/objects/floors/protos/RectangleArena.proto"

WorldInfo {
  ERP 0.8
  basicTimeStep 2
  dragForceScale 1000
  contactProperties [
    ContactProperties {
      material2 "body"
      coulombFriction [
        0.5
      ]
    }
    ContactProperties {
    }
  ]
}
Viewpoint {
  orientation 0.14043362033065374 0.06697400395759646 -0.987822292254388 2.253263981428787
  position 1.2852331067331322 1.8386826480804772 0.968778024774525
}
TexturedBackground {
}
TexturedBackgroundLight {
}
RectangleArena {
  floorSize 100 100
}
Robot {
  name "Ros2Supervisor"
  controller "<extern>"
  supervisor TRUE
}
Robot {
  translation 0 0 0.3
  children [
    Accelerometer {
    }
    InertialUnit {
      name "imu"
    }
    Gyro {
    }
    GPS {
    }
    Shape {
      appearance DEF meshes PBRAppearance {
        baseColor 0.89804 0.91765 0.92941
        roughness 1
        metalness 0
      }
      geometry DEF base_link Mesh {
        url [
          "../meshes/base_link.STL"
        ]
      }
    }
    HingeJoint {
      jointParameters HingeJointParameters {
        axis 0 1 0
        anchor 0 -0.1815 0
        minStop -3.14
        maxStop 3.14
        dampingConstant 0.01
      }
      device [
        RotationalMotor {
          name "right_rear1_joint"
          maxVelocity 10.472
          minPosition -3.14
          maxPosition 3.14
          maxTorque 100
        }
        PositionSensor {
          name "right_rear1_joint_sensor"
        }
      ]
      endPoint Solid {
        translation 0 -0.1815 0
        children [
          Shape {
            appearance USE meshes
            geometry DEF right_rear1_link Mesh {
              url [
                "../meshes/right_rear1_link.STL"
              ]
            }
          }
          HingeJoint {
            jointParameters HingeJointParameters {
              axis 0 1 0
              anchor -0.215 -0.018 0
              minStop -0.05
              maxStop 1.05
              dampingConstant 0.01
            }
            device [
              RotationalMotor {
                name "right_rear2_joint"
                maxVelocity 10.472
                minPosition -0.05
                maxPosition 1.05
                maxTorque 100
              }
              PositionSensor {
                name "right_rear2_joint_sensor"
              }
            ]
            endPoint Solid {
              translation -0.215 -0.018 0
              children [
                Shape {
                  appearance USE meshes
                  geometry DEF right_rear2_link Mesh {
                    url [
                      "../meshes/right_rear2_link.STL"
                    ]
                  }
                }
                HingeJoint {
                  jointParameters HingeJointParameters {
                    axis 0 1 0
                    anchor 0.20521 0 -0.14968
                    dampingConstant 0.01
                  }
                  device [
                    RotationalMotor {
                      name "right_wheel_joint"
                      maxVelocity 52.229
                    }
                    PositionSensor {
                      name "right_wheel_joint_sensor"
                    }
                  ]
                  endPoint Solid {
                    translation 0.20521 0 -0.14968
                    children [
                      Shape {
                        appearance USE meshes
                        geometry DEF right_wheel_link Mesh {
                          url [
                            "../meshes/right_wheel_link.STL"
                          ]
                        }
                      }
                    ]
                    name "right_wheel_link"
                    boundingObject Pose {
                      translation 0 -0.018 0
                      rotation 1 0 0 1.5707996938995747
                      children [
                        Cylinder {
                          height 0.025
                          radius 0.06
                        }
                      ]
                    }
                    physics Physics {
                      density -1
                      mass 0.309755
                      centerOfMass [
                        0.000104 -0.012847 -1.1e-05
                      ]
                      inertiaMatrix [
                        0.0003104314 0.0005717239 0.0003097088
                        -2.369338e-07 -1.477475e-07 4.759622e-08
                      ]
                    }
                  }
                }
                HingeJoint {
                  jointParameters HingeJointParameters {
                    axis 0 1 0
                    anchor -0.002711 -0.001 -0.042914
                  }
                  endPoint Solid {
                    translation -0.002711 -0.001 -0.042914
                    children [
                      Shape {
                        appearance DEF right_guide_link_material PBRAppearance {
                          baseColor 0.698039 0.698039 0.698039
                          roughness 1
                          metalness 0
                        }
                        geometry DEF right_guide_link Mesh {
                          url [
                            "../meshes/right_guide_link.STL"
                          ]
                        }
                      }
                    ]
                    name "right_guide_link"
                    boundingObject Group {
                      children [
                        Pose {
                          translation 0 -0.006 0
                          rotation 1 0 0 1.5707996938995747
                          children [
                            Cylinder {
                              height 0.012
                              radius 0.016
                            }
                          ]
                        }
                      ]
                    }
                    physics Physics {
                      density -1
                      mass 0.012576
                      centerOfMass [
                        0 -0.006 0
                      ]
                      inertiaMatrix [
                        1.006114e-06 1.710394e-06 1.006114e-06
                        -6.382964e-21 -6.283598e-24 -1.467431e-22
                      ]
                    }
                  }
                }
              ]
              name "right_rear2_link"
              boundingObject Group {
                children [
                  Pose {
                    translation 0.1 0.005 -0.07
                    rotation 0 1 0 0.63
                    children [
                      Box {
                        size 0.28 0.015 0.05
                      }
                    ]
                  }
                ]
              }
              physics Physics {
                density -1
                mass 0.368981
                centerOfMass [
                  0.066508 0.005602 -0.052467
                ]
                inertiaMatrix [
                  0.0007435101 0.002037486 0.001309601
                  2.042353e-06 0.0008739154 -2.270599e-06
                ]
              }
            }
          }
        ]
        name "right_rear1_link"
        boundingObject USE right_rear1_link
        physics Physics {
          density -1
          mass 0.440862
          centerOfMass [
            -0.106332 0.004491 0.000587
          ]
          inertiaMatrix [
            0.000136067 0.001579044 0.00146971
            -1.82842e-06 3.985031e-05 6.783866e-07
          ]
        }
      }
    }
    HingeJoint {
      jointParameters HingeJointParameters {
        axis 0 1 0
        anchor 0 0.1815 0
        minStop -3.14
        maxStop 3.14
        dampingConstant 0.01
      }
      device [
        RotationalMotor {
          name "left_rear1_joint"
          maxVelocity 10.472
          minPosition -3.14
          maxPosition 3.14
          maxTorque 100
        }
        PositionSensor {
          name "left_rear1_joint_sensor"
        }
      ]
      endPoint Solid {
        translation 0 0.1815 0
        children [
          Shape {
            appearance USE meshes
            geometry DEF left_rear1_link Mesh {
              url [
                "../meshes/left_rear1_link.STL"
              ]
            }
          }
          HingeJoint {
            jointParameters HingeJointParameters {
              axis 0 1 0
              anchor -0.21499 0.018 0.002019
              minStop -0.05
              maxStop 1.05
              dampingConstant 0.01
            }
            device [
              RotationalMotor {
                name "left_rear2_joint"
                maxVelocity 10.472
                minPosition -0.05
                maxPosition 1.05
                maxTorque 100
              }
              PositionSensor {
                name "left_rear2_joint_sensor"
              }
            ]
            endPoint Solid {
              translation -0.21499 0.018 0.002019
              children [
                Shape {
                  appearance USE meshes
                  geometry DEF left_rear2_link Mesh {
                    url [
                      "../meshes/left_rear2_link.STL"
                    ]
                  }
                }
                HingeJoint {
                  jointParameters HingeJointParameters {
                    axis 0 1 0
                    anchor 0.2038 0 -0.1516
                    dampingConstant 0.01
                  }
                  device [
                    RotationalMotor {
                      name "left_wheel_joint"
                      maxVelocity 52.229
                    }
                    PositionSensor {
                      name "left_wheel_joint_sensor"
                    }
                  ]
                  endPoint Solid {
                    translation 0.2038 0 -0.1516
                    children [
                      Shape {
                        appearance USE meshes
                        geometry DEF left_wheel_link Mesh {
                          url [
                            "../meshes/left_wheel_link.STL"
                          ]
                        }
                      }
                    ]
                    name "left_wheel_link"
                    boundingObject Pose {
                      translation 0 0.018 0
                      rotation 1 0 0 1.5707996938995747
                      children [
                        Cylinder {
                          height 0.025
                          radius 0.06
                        }
                      ]
                    }
                    physics Physics {
                      density -1
                      mass 0.304045
                      centerOfMass [
                        4.2e-05 0.013501 -9.8e-05
                      ]
                      inertiaMatrix [
                        0.0003087478 0.0005695846 0.000309176
                        1.157101e-07 -3.264075e-07 -2.121655e-07
                      ]
                    }
                  }
                }
                HingeJoint {
                  jointParameters HingeJointParameters {
                    axis 0 1 0
                    anchor -0.002027 0.001 -0.042952
                  }
                  endPoint Solid {
                    translation -0.002027 0.001 -0.042952
                    children [
                      Shape {
                        appearance DEF left_guide_link_material PBRAppearance {
                          baseColor 0.698039 0.698039 0.698039
                          roughness 1
                          metalness 0
                        }
                        geometry DEF left_guide_link Mesh {
                          url [
                            "../meshes/left_guide_link.STL"
                          ]
                        }
                      }
                    ]
                    name "left_guide_link"
                    boundingObject Group {
                      children [
                        Pose {
                          translation 0 0.006 0
                          rotation 1 0 0 1.5707996938995747
                          children [
                            Cylinder {
                              height 0.012
                              radius 0.016
                            }
                          ]
                        }
                      ]
                    }
                    physics Physics {
                      density -1
                      mass 0.012576
                      centerOfMass [
                        0 0.006 0
                      ]
                      inertiaMatrix [
                        1.006114e-06 1.710394e-06 1.006114e-06
                        -2.963554e-22 -1.196322e-24 7.893373e-22
                      ]
                    }
                  }
                }
              ]
              name "left_rear2_link"
              boundingObject Group {
                children [
                  Pose {
                    translation 0.1 -0.005 -0.07
                    rotation 0 1 0 0.63
                    children [
                      Box {
                        size 0.28 0.015 0.05
                      }
                    ]
                  }
                ]
              }
              physics Physics {
                density -1
                mass 0.309018
                centerOfMass [
                  0.078443 -0.005577 -0.063298
                ]
                inertiaMatrix [
                  0.0007583587 0.002015399 0.001272167
                  -2.058355e-06 0.0008810833 2.216263e-06
                ]
              }
            }
          }
        ]
        name "left_rear1_link"
        boundingObject USE left_rear1_link
        physics Physics {
          density -1
          mass 0.503388
          centerOfMass [
            -0.118949 -0.002609 0.001637
          ]
          inertiaMatrix [
            0.0001471624 0.001609354 0.001489392
            1.831268e-06 5.290913e-05 -7.0073e-07
          ]
        }
      }
    }
  ]
  name "wheelbipe25_v3_serial"
  contactMaterial "body"
  boundingObject Group {
    children [
      Pose {
        translation 0 0 0.075
        children [
          Box {
            size 0.275 0.275 0.43
          }
        ]
      }
      Pose {
        translation 0 0 -0.035
        children [
          Box {
            size 0.54 0.3 0.16
          }
        ]
      }
    ]
  }
  physics Physics {
    density -1
    mass 13.643
    centerOfMass [
      0.003404 0.005444 0.026919
    ]
    inertiaMatrix [
      0.017406 0.023837 0.027425
      -3.2184e-05 9.9775e-05 -3.6499e-05
    ]
  }
  controller "<extern>"
}
